<robot name = "robot">
    <link name="0">
        <inertial>
            <origin xyz="0 0 0.35" rpy="0 0 0"/>
            <mass value="1" />
            <inertia ixx="100" ixy="0" ixz="0" iyy="100" iyz="0" izz="100" />
        </inertial>
        <visual>
            <origin xyz="0 0 0.35" rpy="0 0 0"/>
            <geometry>
                <box size="0.3 0.3 0.3" />
            </geometry>
            <material name="Cyan">
                <color rgba="0 1.0 1.0 1.0"/>
            </material>
        </visual>
        <collision>
            <origin xyz="0 0 0.35" rpy="0 0 0"/>
            <geometry>
                <box size="0.3 0.3 0.3" />
            </geometry>
        </collision>
    </link>
    <joint name="0-1" type="fixed">
       <parent link="0"/>
       <child  link="1"/>
       <origin rpy="0 0 0" xyz="0 0 0" />
       <axis xyz="0 1 0"/>
       <limit effort="0.0" lower="-3" upper="3" velocity="0.0"/>
    </joint>
    <link name="1">
        <inertial>
            <origin xyz="0 0.2 0.19999999999999998" rpy="0 0 0"/>
            <mass value="1" />
            <inertia ixx="100" ixy="0" ixz="0" iyy="100" iyz="0" izz="100" />
        </inertial>
        <visual>
            <origin xyz="0 0.2 0.19999999999999998" rpy="0 0 0"/>
            <geometry>
                <box size="0.1 0.1 0.15" />
            </geometry>
            <material name="Cyan">
                <color rgba="0 1.0 1.0 1.0"/>
            </material>
        </visual>
        <collision>
            <origin xyz="0 0.2 0.19999999999999998" rpy="0 0 0"/>
            <geometry>
                <box size="0.1 0.1 0.15" />
            </geometry>
        </collision>
    </link>
    <joint name="1-2" type="revolute">
       <parent link="1"/>
       <child  link="2"/>
       <origin rpy="0 0 0" xyz="0 0.05 0" />
       <axis xyz="0 1 0"/>
       <limit effort="0.0" lower="-3" upper="3" velocity="0.0"/>
    </joint>
    <link name="2">
        <inertial>
            <origin xyz="0 0.15 0.049999999999999996" rpy="0 0 0"/>
            <mass value="1" />
            <inertia ixx="100" ixy="0" ixz="0" iyy="100" iyz="0" izz="100" />
        </inertial>
        <visual>
            <origin xyz="0 0.15 0.049999999999999996" rpy="0 0 0"/>
            <geometry>
                <box size="0.1 0.1 0.15" />
            </geometry>
            <material name="Cyan">
                <color rgba="0 1.0 1.0 1.0"/>
            </material>
        </visual>
        <collision>
            <origin xyz="0 0.15 0.049999999999999996" rpy="0 0 0"/>
            <geometry>
                <box size="0.1 0.1 0.15" />
            </geometry>
        </collision>
    </link>
    <joint name="0-3" type="fixed">
       <parent link="0"/>
       <child  link="3"/>
       <origin rpy="0 0 0" xyz="0 0 0" />
       <axis xyz="1 0 0"/>
       <limit effort="0.0" lower="-3" upper="3" velocity="0.0"/>
    </joint>
    <link name="3">
        <inertial>
            <origin xyz="0 -0.2 0.19999999999999998" rpy="0 0 0"/>
            <mass value="1" />
            <inertia ixx="100" ixy="0" ixz="0" iyy="100" iyz="0" izz="100" />
        </inertial>
        <visual>
            <origin xyz="0 -0.2 0.19999999999999998" rpy="0 0 0"/>
            <geometry>
                <box size="0.1 0.1 0.15" />
            </geometry>
            <material name="Cyan">
                <color rgba="0 1.0 1.0 1.0"/>
            </material>
        </visual>
        <collision>
            <origin xyz="0 -0.2 0.19999999999999998" rpy="0 0 0"/>
            <geometry>
                <box size="0.1 0.1 0.15" />
            </geometry>
        </collision>
    </link>
    <joint name="3-4" type="revolute">
       <parent link="3"/>
       <child  link="4"/>
       <origin rpy="0 0 0" xyz="0 -0.05 0" />
       <axis xyz="1 0 0"/>
       <limit effort="0.0" lower="-3" upper="3" velocity="0.0"/>
    </joint>
    <link name="4">
        <inertial>
            <origin xyz="0 -0.15 0.049999999999999996" rpy="0 0 0"/>
            <mass value="1" />
            <inertia ixx="100" ixy="0" ixz="0" iyy="100" iyz="0" izz="100" />
        </inertial>
        <visual>
            <origin xyz="0 -0.15 0.049999999999999996" rpy="0 0 0"/>
            <geometry>
                <box size="0.1 0.1 0.15" />
            </geometry>
            <material name="Cyan">
                <color rgba="0 1.0 1.0 1.0"/>
            </material>
        </visual>
        <collision>
            <origin xyz="0 -0.15 0.049999999999999996" rpy="0 0 0"/>
            <geometry>
                <box size="0.1 0.1 0.15" />
            </geometry>
        </collision>
    </link>
    <joint name="0-5" type="fixed">
       <parent link="0"/>
       <child  link="5"/>
       <origin rpy="0 0 0" xyz="0 0 0" />
       <axis xyz="0 1 0"/>
       <limit effort="0.0" lower="-3" upper="3" velocity="0.0"/>
    </joint>
    <link name="5">
        <inertial>
            <origin xyz="-0.2 0 0.19999999999999998" rpy="0 0 0"/>
            <mass value="1" />
            <inertia ixx="100" ixy="0" ixz="0" iyy="100" iyz="0" izz="100" />
        </inertial>
        <visual>
            <origin xyz="-0.2 0 0.19999999999999998" rpy="0 0 0"/>
            <geometry>
                <box size="0.1 0.1 0.15" />
            </geometry>
            <material name="Cyan">
                <color rgba="0 1.0 1.0 1.0"/>
            </material>
        </visual>
        <collision>
            <origin xyz="-0.2 0 0.19999999999999998" rpy="0 0 0"/>
            <geometry>
                <box size="0.1 0.1 0.15" />
            </geometry>
        </collision>
    </link>
    <joint name="5-6" type="revolute">
       <parent link="5"/>
       <child  link="6"/>
       <origin rpy="0 0 0" xyz="-0.05 0 0" />
       <axis xyz="0 1 0"/>
       <limit effort="0.0" lower="-3" upper="3" velocity="0.0"/>
    </joint>
    <link name="6">
        <inertial>
            <origin xyz="-0.15 0 0.049999999999999996" rpy="0 0 0"/>
            <mass value="1" />
            <inertia ixx="100" ixy="0" ixz="0" iyy="100" iyz="0" izz="100" />
        </inertial>
        <visual>
            <origin xyz="-0.15 0 0.049999999999999996" rpy="0 0 0"/>
            <geometry>
                <box size="0.1 0.1 0.15" />
            </geometry>
            <material name="Cyan">
                <color rgba="0 1.0 1.0 1.0"/>
            </material>
        </visual>
        <collision>
            <origin xyz="-0.15 0 0.049999999999999996" rpy="0 0 0"/>
            <geometry>
                <box size="0.1 0.1 0.15" />
            </geometry>
        </collision>
    </link>
    <joint name="0-7" type="fixed">
       <parent link="0"/>
       <child  link="7"/>
       <origin rpy="0 0 0" xyz="0 0 0" />
       <axis xyz="1 0 0"/>
       <limit effort="0.0" lower="-3" upper="3" velocity="0.0"/>
    </joint>
    <link name="7">
        <inertial>
            <origin xyz="0.2 0 0.19999999999999998" rpy="0 0 0"/>
            <mass value="1" />
            <inertia ixx="100" ixy="0" ixz="0" iyy="100" iyz="0" izz="100" />
        </inertial>
        <visual>
            <origin xyz="0.2 0 0.19999999999999998" rpy="0 0 0"/>
            <geometry>
                <box size="0.1 0.1 0.15" />
            </geometry>
            <material name="Cyan">
                <color rgba="0 1.0 1.0 1.0"/>
            </material>
        </visual>
        <collision>
            <origin xyz="0.2 0 0.19999999999999998" rpy="0 0 0"/>
            <geometry>
                <box size="0.1 0.1 0.15" />
            </geometry>
        </collision>
    </link>
    <joint name="7-8" type="revolute">
       <parent link="7"/>
       <child  link="8"/>
       <origin rpy="0 0 0" xyz="0.05 0 0" />
       <axis xyz="1 0 0"/>
       <limit effort="0.0" lower="-3" upper="3" velocity="0.0"/>
    </joint>
    <link name="8">
        <inertial>
            <origin xyz="0.15 0 0.049999999999999996" rpy="0 0 0"/>
            <mass value="1" />
            <inertia ixx="100" ixy="0" ixz="0" iyy="100" iyz="0" izz="100" />
        </inertial>
        <visual>
            <origin xyz="0.15 0 0.049999999999999996" rpy="0 0 0"/>
            <geometry>
                <box size="0.1 0.1 0.15" />
            </geometry>
            <material name="Cyan">
                <color rgba="0 1.0 1.0 1.0"/>
            </material>
        </visual>
        <collision>
            <origin xyz="0.15 0 0.049999999999999996" rpy="0 0 0"/>
            <geometry>
                <box size="0.1 0.1 0.15" />
            </geometry>
        </collision>
    </link>
</robot>