<robot name = "robot">
    <link name="Body">
        <inertial>
            <origin xyz="0 0 0.06" rpy="0 0 0"/>
            <mass value="1" />
            <inertia ixx="100" ixy="0" ixz="0" iyy="100" iyz="0" izz="100" />
        </inertial>
        <visual>
            <origin xyz="0 0 0.06" rpy="0 0 0"/>
            <geometry>
                <box size="0.12 0.12 0.12" />
            </geometry>
            <material name="Cyan">
                <color rgba="0 1.0 1.0 1.0"/>
            </material>
        </visual>
        <collision>
            <origin xyz="0 0 0.06" rpy="0 0 0"/>
            <geometry>
                <box size="0.12 0.12 0.12" />
            </geometry>
        </collision>
    </link>
    <joint name="Front_hip" type="revolute">
       <parent link="Body"/>
       <child  link="Front_upper"/>
       <origin rpy="0 0 0" xyz="0.0 0.06 0.03" />
       <axis xyz="0 1 0"/>
       <limit effort="0.0" lower="-3.14159" upper="3.14159" velocity="0.0"/>
    </joint>
    <link name="Front_upper">
        <inertial>
            <origin xyz="0 0.02 -0.02" rpy="0 0 0"/>
            <mass value="1" />
            <inertia ixx="100" ixy="0" ixz="0" iyy="100" iyz="0" izz="100" />
        </inertial>
        <visual>
            <origin xyz="0 0.02 -0.02" rpy="0 0 0"/>
            <geometry>
                <box size="0.02 0.04 0.04" />
            </geometry>
            <material name="Cyan">
                <color rgba="0 1.0 1.0 1.0"/>
            </material>
        </visual>
        <collision>
            <origin xyz="0 0.02 -0.02" rpy="0 0 0"/>
            <geometry>
                <box size="0.02 0.04 0.04" />
            </geometry>
        </collision>
    </link>
    <joint name="Front_knee" type="revolute">
       <parent link="Front_upper"/>
       <child  link="Front_lower"/>
       <origin rpy="0 0 0" xyz="0 0.04 -0.04" />
       <axis xyz="0 1 0"/>
       <limit effort="0.0" lower="-3.14159" upper="3.14159" velocity="0.0"/>
    </joint>
    <link name="Front_lower">
        <inertial>
            <origin xyz="0 0.02 -0.04" rpy="0 0 0"/>
            <mass value="1" />
            <inertia ixx="100" ixy="0" ixz="0" iyy="100" iyz="0" izz="100" />
        </inertial>
        <visual>
            <origin xyz="0 0.02 -0.04" rpy="0 0 0"/>
            <geometry>
                <box size="0.02 0.04 0.04" />
            </geometry>
            <material name="Cyan">
                <color rgba="0 1.0 1.0 1.0"/>
            </material>
        </visual>
        <collision>
            <origin xyz="0 0.02 -0.04" rpy="0 0 0"/>
            <geometry>
                <box size="0.02 0.04 0.04" />
            </geometry>
        </collision>
    </link>
    <joint name="Right_hip" type="revolute">
       <parent link="Body"/>
       <child  link="Right_upper"/>
       <origin rpy="0 0 0" xyz="0.06 0.0 0.03" />
       <axis xyz="0 1 0"/>
       <limit effort="0.0" lower="-3.14159" upper="3.14159" velocity="0.0"/>
    </joint>
    <link name="Right_upper">
        <inertial>
            <origin xyz="0 0.02 -0.02" rpy="0 0 0"/>
            <mass value="1" />
            <inertia ixx="100" ixy="0" ixz="0" iyy="100" iyz="0" izz="100" />
        </inertial>
        <visual>
            <origin xyz="0 0.02 -0.02" rpy="0 0 0"/>
            <geometry>
                <box size="0.02 0.04 0.04" />
            </geometry>
            <material name="Cyan">
                <color rgba="0 1.0 1.0 1.0"/>
            </material>
        </visual>
        <collision>
            <origin xyz="0 0.02 -0.02" rpy="0 0 0"/>
            <geometry>
                <box size="0.02 0.04 0.04" />
            </geometry>
        </collision>
    </link>
    <joint name="Right_knee" type="revolute">
       <parent link="Right_upper"/>
       <child  link="Right_lower"/>
       <origin rpy="0 0 0" xyz="0 0.04 -0.04" />
       <axis xyz="0 1 0"/>
       <limit effort="0.0" lower="-3.14159" upper="3.14159" velocity="0.0"/>
    </joint>
    <link name="Right_lower">
        <inertial>
            <origin xyz="0 0.02 -0.04" rpy="0 0 0"/>
            <mass value="1" />
            <inertia ixx="100" ixy="0" ixz="0" iyy="100" iyz="0" izz="100" />
        </inertial>
        <visual>
            <origin xyz="0 0.02 -0.04" rpy="0 0 0"/>
            <geometry>
                <box size="0.02 0.04 0.04" />
            </geometry>
            <material name="Cyan">
                <color rgba="0 1.0 1.0 1.0"/>
            </material>
        </visual>
        <collision>
            <origin xyz="0 0.02 -0.04" rpy="0 0 0"/>
            <geometry>
                <box size="0.02 0.04 0.04" />
            </geometry>
        </collision>
    </link>
    <joint name="Back_hip" type="revolute">
       <parent link="Body"/>
       <child  link="Back_upper"/>
       <origin rpy="0 0 0" xyz="0.0 -0.06 0.03" />
       <axis xyz="0 1 0"/>
       <limit effort="0.0" lower="-3.14159" upper="3.14159" velocity="0.0"/>
    </joint>
    <link name="Back_upper">
        <inertial>
            <origin xyz="0 0.02 -0.02" rpy="0 0 0"/>
            <mass value="1" />
            <inertia ixx="100" ixy="0" ixz="0" iyy="100" iyz="0" izz="100" />
        </inertial>
        <visual>
            <origin xyz="0 0.02 -0.02" rpy="0 0 0"/>
            <geometry>
                <box size="0.02 0.04 0.04" />
            </geometry>
            <material name="Cyan">
                <color rgba="0 1.0 1.0 1.0"/>
            </material>
        </visual>
        <collision>
            <origin xyz="0 0.02 -0.02" rpy="0 0 0"/>
            <geometry>
                <box size="0.02 0.04 0.04" />
            </geometry>
        </collision>
    </link>
    <joint name="Back_knee" type="revolute">
       <parent link="Back_upper"/>
       <child  link="Back_lower"/>
       <origin rpy="0 0 0" xyz="0 0.04 -0.04" />
       <axis xyz="0 1 0"/>
       <limit effort="0.0" lower="-3.14159" upper="3.14159" velocity="0.0"/>
    </joint>
    <link name="Back_lower">
        <inertial>
            <origin xyz="0 0.02 -0.04" rpy="0 0 0"/>
            <mass value="1" />
            <inertia ixx="100" ixy="0" ixz="0" iyy="100" iyz="0" izz="100" />
        </inertial>
        <visual>
            <origin xyz="0 0.02 -0.04" rpy="0 0 0"/>
            <geometry>
                <box size="0.02 0.04 0.04" />
            </geometry>
            <material name="Cyan">
                <color rgba="0 1.0 1.0 1.0"/>
            </material>
        </visual>
        <collision>
            <origin xyz="0 0.02 -0.04" rpy="0 0 0"/>
            <geometry>
                <box size="0.02 0.04 0.04" />
            </geometry>
        </collision>
    </link>
    <joint name="Left_hip" type="revolute">
       <parent link="Body"/>
       <child  link="Left_upper"/>
       <origin rpy="0 0 0" xyz="-0.06 0.0 0.03" />
       <axis xyz="0 1 0"/>
       <limit effort="0.0" lower="-3.14159" upper="3.14159" velocity="0.0"/>
    </joint>
    <link name="Left_upper">
        <inertial>
            <origin xyz="0 0.02 -0.02" rpy="0 0 0"/>
            <mass value="1" />
            <inertia ixx="100" ixy="0" ixz="0" iyy="100" iyz="0" izz="100" />
        </inertial>
        <visual>
            <origin xyz="0 0.02 -0.02" rpy="0 0 0"/>
            <geometry>
                <box size="0.02 0.04 0.04" />
            </geometry>
            <material name="Cyan">
                <color rgba="0 1.0 1.0 1.0"/>
            </material>
        </visual>
        <collision>
            <origin xyz="0 0.02 -0.02" rpy="0 0 0"/>
            <geometry>
                <box size="0.02 0.04 0.04" />
            </geometry>
        </collision>
    </link>
    <joint name="Left_knee" type="revolute">
       <parent link="Left_upper"/>
       <child  link="Left_lower"/>
       <origin rpy="0 0 0" xyz="0 0.04 -0.04" />
       <axis xyz="0 1 0"/>
       <limit effort="0.0" lower="-3.14159" upper="3.14159" velocity="0.0"/>
    </joint>
    <link name="Left_lower">
        <inertial>
            <origin xyz="0 0.02 -0.04" rpy="0 0 0"/>
            <mass value="1" />
            <inertia ixx="100" ixy="0" ixz="0" iyy="100" iyz="0" izz="100" />
        </inertial>
        <visual>
            <origin xyz="0 0.02 -0.04" rpy="0 0 0"/>
            <geometry>
                <box size="0.02 0.04 0.04" />
            </geometry>
            <material name="Cyan">
                <color rgba="0 1.0 1.0 1.0"/>
            </material>
        </visual>
        <collision>
            <origin xyz="0 0.02 -0.04" rpy="0 0 0"/>
            <geometry>
                <box size="0.02 0.04 0.04" />
            </geometry>
        </collision>
    </link>
</robot>